### 1.8 try catch

특정 코드의 문제가 생겼을 때 에러를 잡기 위해 사용한다.

~~~dart
try{
  //코드 실행
} catch(e){
  //에러 처리
}
~~~

try로 감싼 로직에서 코드를 실행하고, 만약 에러가 생기면 try 구문을 멈추고 catch로 넘어간다.

~~~dart
try{
  print("try문 실행");
} catch(e){
  print("catch문 실행");
}
~~~

> 실행결과 : 
>
> try문 실행

에러가 나지 않았기 때문에 catch문 안에 있는 print문은 실행되지 않는다.

~~~dart
try{
  print("try문 실행");
  throw Exception("에러 발생시키기");
  print("try문 종료");
} catch(e){
  print("catch문 실행");
}
~~~

> 실행결과 : 
>
> try문 실행
>
> catch문 실행

에러를 일부러 발생시키는 throw 키워드를 이용했더니 try 구문의 "try문 종료" 프린트문은 출력되지 않고 catch로 넘어가는 모습이다.